Traceback (most recent call last):
  File "/home/aghktb/GRN/GRNformer/GRNFlow_Train.py", line 306, in <module>
    train_GRNFormerLinkPred()
  File "/home/aghktb/GRN/GRNformer/GRNFlow_Train.py", line 299, in train_GRNFormerLinkPred
    trainer.fit(model, train_loader, valid_loader)
  File "/home/aghktb/miniconda3/envs/myenv/lib/python3.11/site-packages/lightning/pytorch/trainer/trainer.py", line 603, in fit
    call._call_and_handle_interrupt(
  File "/home/aghktb/miniconda3/envs/myenv/lib/python3.11/site-packages/lightning/pytorch/trainer/call.py", line 36, in _call_and_handle_interrupt
    return trainer.strategy.launcher.launch(trainer_fn, *args, trainer=trainer, **kwargs)
           ^^^^^^^^^^^^^^^^^^^^^^^^^^^^^^^^^^^^^^^^^^^^^^^^^^^^^^^^^^^^^^^^^^^^^^^^^^^^^^
  File "/home/aghktb/miniconda3/envs/myenv/lib/python3.11/site-packages/lightning/pytorch/strategies/launchers/multiprocessing.py", line 113, in launch
    mp.start_processes(
  File "/home/aghktb/miniconda3/envs/myenv/lib/python3.11/site-packages/torch/multiprocessing/spawn.py", line 197, in start_processes
    while not context.join():
              ^^^^^^^^^^^^^^
  File "/home/aghktb/miniconda3/envs/myenv/lib/python3.11/site-packages/torch/multiprocessing/spawn.py", line 160, in join
    raise ProcessRaisedException(msg, error_index, failed_process.pid)
torch.multiprocessing.spawn.ProcessRaisedException:
-- Process 1 terminated with the following error:
Traceback (most recent call last):
  File "/home/aghktb/miniconda3/envs/myenv/lib/python3.11/site-packages/torch/multiprocessing/spawn.py", line 69, in _wrap
    fn(i, *args)
  File "/home/aghktb/miniconda3/envs/myenv/lib/python3.11/site-packages/lightning/pytorch/strategies/launchers/multiprocessing.py", line 139, in _wrapping_function
    results = function(*args, **kwargs)
              ^^^^^^^^^^^^^^^^^^^^^^^^^
  File "/home/aghktb/miniconda3/envs/myenv/lib/python3.11/site-packages/lightning/pytorch/trainer/trainer.py", line 645, in _fit_impl
    self._run(model, ckpt_path=self.ckpt_path)
  File "/home/aghktb/miniconda3/envs/myenv/lib/python3.11/site-packages/lightning/pytorch/trainer/trainer.py", line 1098, in _run
    results = self._run_stage()
              ^^^^^^^^^^^^^^^^^
  File "/home/aghktb/miniconda3/envs/myenv/lib/python3.11/site-packages/lightning/pytorch/trainer/trainer.py", line 1177, in _run_stage
    self._run_train()
  File "/home/aghktb/miniconda3/envs/myenv/lib/python3.11/site-packages/lightning/pytorch/trainer/trainer.py", line 1190, in _run_train
    self._run_sanity_check()
  File "/home/aghktb/miniconda3/envs/myenv/lib/python3.11/site-packages/lightning/pytorch/trainer/trainer.py", line 1262, in _run_sanity_check
    val_loop.run()
  File "/home/aghktb/miniconda3/envs/myenv/lib/python3.11/site-packages/lightning/pytorch/loops/loop.py", line 199, in run
    self.advance(*args, **kwargs)
  File "/home/aghktb/miniconda3/envs/myenv/lib/python3.11/site-packages/lightning/pytorch/loops/dataloader/evaluation_loop.py", line 152, in advance
    dl_outputs = self.epoch_loop.run(self._data_fetcher, dl_max_batches, kwargs)
                 ^^^^^^^^^^^^^^^^^^^^^^^^^^^^^^^^^^^^^^^^^^^^^^^^^^^^^^^^^^^^^^^
  File "/home/aghktb/miniconda3/envs/myenv/lib/python3.11/site-packages/lightning/pytorch/loops/loop.py", line 199, in run
    self.advance(*args, **kwargs)
  File "/home/aghktb/miniconda3/envs/myenv/lib/python3.11/site-packages/lightning/pytorch/loops/epoch/evaluation_epoch_loop.py", line 137, in advance
    output = self._evaluation_step(**kwargs)
             ^^^^^^^^^^^^^^^^^^^^^^^^^^^^^^^
  File "/home/aghktb/miniconda3/envs/myenv/lib/python3.11/site-packages/lightning/pytorch/loops/epoch/evaluation_epoch_loop.py", line 234, in _evaluation_step
    output = self.trainer._call_strategy_hook(hook_name, *kwargs.values())
             ^^^^^^^^^^^^^^^^^^^^^^^^^^^^^^^^^^^^^^^^^^^^^^^^^^^^^^^^^^^^^
  File "/home/aghktb/miniconda3/envs/myenv/lib/python3.11/site-packages/lightning/pytorch/trainer/trainer.py", line 1480, in _call_strategy_hook
    output = fn(*args, **kwargs)
             ^^^^^^^^^^^^^^^^^^^
  File "/home/aghktb/miniconda3/envs/myenv/lib/python3.11/site-packages/lightning/pytorch/strategies/ddp_spawn.py", line 288, in validation_step
    return self.model(*args, **kwargs)
           ^^^^^^^^^^^^^^^^^^^^^^^^^^^
  File "/home/aghktb/miniconda3/envs/myenv/lib/python3.11/site-packages/torch/nn/modules/module.py", line 1501, in _call_impl
    return forward_call(*args, **kwargs)
           ^^^^^^^^^^^^^^^^^^^^^^^^^^^^^
  File "/home/aghktb/miniconda3/envs/myenv/lib/python3.11/site-packages/torch/nn/parallel/distributed.py", line 1156, in forward
    output = self._run_ddp_forward(*inputs, **kwargs)
             ^^^^^^^^^^^^^^^^^^^^^^^^^^^^^^^^^^^^^^^^
  File "/home/aghktb/miniconda3/envs/myenv/lib/python3.11/site-packages/torch/nn/parallel/distributed.py", line 1110, in _run_ddp_forward
    return module_to_run(*inputs[0], **kwargs[0])  # type: ignore[index]
           ^^^^^^^^^^^^^^^^^^^^^^^^^^^^^^^^^^^^^^
  File "/home/aghktb/miniconda3/envs/myenv/lib/python3.11/site-packages/torch/nn/modules/module.py", line 1501, in _call_impl
    return forward_call(*args, **kwargs)
           ^^^^^^^^^^^^^^^^^^^^^^^^^^^^^
  File "/home/aghktb/miniconda3/envs/myenv/lib/python3.11/site-packages/lightning/pytorch/overrides/base.py", line 110, in forward
    return self._forward_module.validation_step(*inputs, **kwargs)
           ^^^^^^^^^^^^^^^^^^^^^^^^^^^^^^^^^^^^^^^^^^^^^^^^^^^^^^^
  File "/home/aghktb/GRN/GRNformer/GRNFlow_Train.py", line 189, in validation_step
    self.log_dict(metric_valid)
  File "/home/aghktb/miniconda3/envs/myenv/lib/python3.11/site-packages/lightning/pytorch/core/module.py", line 511, in log_dict
    self.log(
  File "/home/aghktb/miniconda3/envs/myenv/lib/python3.11/site-packages/lightning/pytorch/core/module.py", line 371, in log
    apply_to_collection(
  File "/home/aghktb/miniconda3/envs/myenv/lib/python3.11/site-packages/lightning_utilities/core/apply_func.py", line 51, in apply_to_collection
    return function(data, *args, **kwargs)
           ^^^^^^^^^^^^^^^^^^^^^^^^^^^^^^^
  File "/home/aghktb/miniconda3/envs/myenv/lib/python3.11/site-packages/lightning/pytorch/core/module.py", line 535, in __check_allowed
    raise ValueError(f"`self.log({name}, {value})` was called, but `{type(v).__name__}` values cannot be logged")
ValueError: `self.log(valid_BinaryPrecisionRecallCurve, (tensor([0.0100, 0.0100, 0.0100,  ..., 0.0677, 0.0678, 1.0000], device='cuda:1'), tensor([1.0000, 0.9898, 0.9898,  ..., 0.6837, 0.6837, 0.0000], device='cuda:1'), tensor([0.5050, 0.5050, 0.5050,  ..., 1.0000, 1.0000, 1.0000], device='cuda:1')))` was called, but `tuple` values cannot be logged